Workbook

Sheet PhanCong
A1: WEALTHFLOW | PHÂN CÔNG TASK & TRACKING
A2: 54 công việc có chủ sở hữu — cập nhật cột H (trạng thái), L (tiến độ %), O (PR/bằng chứng). Thời gian 19/10–15/11/2026 là KẾ HOẠCH ĐỀ XUẤT.
A3: ID | B3: Phân hệ | C3: Công việc | D3: Mô tả chi tiết & tiêu chí nghiệm thu (DoD) | E3: Người phụ trách | F3: Người review | G3: Ưu tiên | H3: Trạng thái | I3: Sprint | J3: Bắt đầu | K3: Hạn cuối | L3: Tiến độ (%) | M3: Phụ thuộc | N3: File/API / tài liệu bàn giao | O3: Link PR / minh chứng | P3: Căn cứ & ghi chú
A4: LEAD-01 | B4: Tích hợp & bảo mật | C4: Rà soát repo, baseline chức năng | D4: Chạy project và chụp màn hình từng trang; đối chiếu thực tế UI/API/MySQL; lập bảng Demo / API-ready / E2E; ghi commit SHA được rà soát. | E4: Võ Trịnh Quốc Huy | F4: Nguyễn Thành Trung | G4: P1 | H4: To Do | I4: S1 | J4: 46314 | K4: 46320 | L4: 0 | M4: — | N4: docs/implementation-status.md | P4: README xác nhận frontend một số phân hệ còn demo.
A5: LEAD-02 | B5: Tích hợp & bảo mật | C5: Chốt kiến trúc module và API contract | D5: Chuẩn hóa router, envelope JSON, HTTP status, validation, auth middleware; thống nhất cách mỗi dev gọi API và nhận lỗi. | E5: Võ Trịnh Quốc Huy | F5: Võ Văn Khôi Nguyên | G5: P1 | H5: To Do | I5: S1 | J5: 46314 | K5: 46320 | L5: 0 | M5: LEAD-01,DB-01 | N5: docs/api-contract.md; source/backend/ | P5: Thiết kế mới/chuẩn hóa, không giả định API nào đã có.
A6: LEAD-03 | B6: Tích hợp & bảo mật | C6: Chuẩn hóa branch, PR và review | D6: Bảo vệ main; dùng feature/<module>-<id>; PR nêu bằng chứng test; không merge nếu thiếu review hoặc phá trang khác. | E6: Võ Trịnh Quốc Huy | F6: Phạm Nguyễn Tuấn Kiệt | G6: P1 | H6: To Do | I6: S1 | J6: 46314 | K6: 46320 | L6: 0 | M6: LEAD-01 | N6: docs/git-workflow.md; .gitignore | P6: Cần áp dụng trong nhóm.
A7: LEAD-04 | B7: Tích hợp & bảo mật | C7: Rà soát auth, session và phân quyền | D7: Test đăng ký/đăng nhập/đăng xuất; session expiry; user chỉ xem dữ liệu của mình; Admin không xem giao dịch riêng. | E7: Võ Trịnh Quốc Huy | F7: Nguyễn Thành Trung | G7: P1 | H7: To Do | I7: S1 | J7: 46314 | K7: 46320 | L7: 0 | M7: DB-01 | N7: source/backend/; source/frontend/js/services/auth-api.js | P7: Auth được README mô tả, cần test E2E.
A8: LEAD-05 | B8: Tích hợp & bảo mật | C8: Kiểm thử OTP và đặt lại mật khẩu | D8: Kiểm OTP 10 phút, tối đa 5 lần theo tài liệu; reset làm vô hiệu hóa mật khẩu cũ; không tiết lộ email tồn tại. | E8: Võ Trịnh Quốc Huy | F8: Nguyễn Thành Trung | G8: P1 | H8: To Do | I8: S1 | J8: 46314 | K8: 46320 | L8: 0 | M8: LEAD-04 | N8: source/backend/; source/frontend/js/landing/main.js | P8: Local email .eml, SMTP thật không phải điều kiện test.
A9: DB-01 | B9: Database & tài liệu | C9: Kiểm kê schema/migration hiện có | D9: Liệt kê bảng, FK/index, version migration; đối chiếu tên thật từ 001_initial_schema.sql; không sửa DB trước khi backup. | E9: Nguyễn Thành Trung | F9: Võ Trịnh Quốc Huy | G9: P1 | H9: To Do | I9: S1 | J9: 46314 | K9: 46320 | L9: 0 | M9: LEAD-01 | N9: docs/data-dictionary.md | P9: Schema chính xác phải lấy từ SQL gốc.
A10: DB-02 | B10: Database & tài liệu | C10: ERD chuẩn và quan hệ per-user | D10: ERD wallet, category, ledger, budget, recurring, goal, loan, gold, notification; mọi dữ liệu tài chính thuộc user; PK/FK rõ. | E10: Nguyễn Thành Trung | F10: Võ Trịnh Quốc Huy | G10: P1 | H10: To Do | I10: S1 | J10: 46314 | K10: 46320 | L10: 0 | M10: DB-01 | N10: docs/erd.mmd; docs/erd.png | P10: Một số bảng mở rộng là đề xuất cần xác nhận.
A11: DB-03 | B11: Database & tài liệu | C11: Data dictionary và ràng buộc SQL | D11: Mô tả trường, kiểu, NOT NULL, UNIQUE, FK, CHECK ứng dụng; money DECIMAL, timestamps, soft archive; kỳ ngân sách uniqueness. | E11: Nguyễn Thành Trung | F11: Võ Văn Khôi Nguyên | G11: P1 | H11: To Do | I11: S1 | J11: 46314 | K11: 46320 | L11: 0 | M11: DB-01 | N11: docs/data-dictionary.md | P11: Dùng tên bảng thực tế; không tự ý reset.
A12: DB-04 | B12: Database & tài liệu | C12: Seed test độc lập và an toàn | D12: Tạo ít nhất 2 user, 2 ví/user, 10 giao dịch đa loại, 3 ngân sách, 2 lịch định kỳ; import không DROP dữ liệu production. | E12: Nguyễn Thành Trung | F12: Võ Văn Khôi Nguyên | G12: P1 | H12: To Do | I12: S1 | J12: 46314 | K12: 46320 | L12: 0 | M12: DB-01 | N12: source/database/seed_demo.sql | P12: Dữ liệu thử không chứa email/mật khẩu thật.
A13: TX-01 | B13: Ví & giao dịch | C13: Chốt giao kèo ví + giao dịch | D13: Liệt kê endpoint cần cho UI wallets/transactions/categories; mapping response và validation; reuse WalletRepository/LedgerService. | E13: Võ Văn Khôi Nguyên | F13: Võ Trịnh Quốc Huy | G13: P1 | H13: To Do | I13: S1 | J13: 46314 | K13: 46320 | L13: 0 | M13: LEAD-02,DB-01 | N13: docs/api-transactions.md | P13: Backend ledger có test SQLite; E2E MySQL chưa xác nhận.
A14: TX-02 | B14: Ví & giao dịch | C14: Ví: CRUD + lưu trữ có điều kiện | D14: Tạo/sửa/xem ví; kiểm tra chủ sở hữu; chỉ lưu trữ khi balance=0 và không ràng buộc lịch active; reload vẫn có dữ liệu. | E14: Võ Văn Khôi Nguyên | F14: Nguyễn Thành Trung | G14: P1 | H14: To Do | I14: S1 | J14: 46314 | K14: 46320 | L14: 0 | M14: TX-01,DB-04 | N14: source/backend/; source/frontend/js/app/pages.js | P14: Trang Ví đang có fixtures.
A15: TX-03 | B15: Ví & giao dịch | C15: Danh mục cá nhân và mặc định | D15: Tạo/đổi tên/lưu trữ danh mục; phân biệt income/expense; không xóa danh mục đã có giao dịch; filter hoạt động. | E15: Võ Văn Khôi Nguyên | F15: Nguyễn Thành Trung | G15: P1 | H15: To Do | I15: S1 | J15: 46314 | K15: 46320 | L15: 0 | M15: TX-01,DB-04 | N15: source/backend/; source/frontend/js/app/pages.js | P15: UI categories đã có mẫu.
A16: PLAN-01 | B16: Ngân sách & tài sản | C16: Khảo sát phần backend ngân sách có sẵn | D16: Kiểm tra BudgetService/Repository và endpoint đang gọi; xác nhận 80/100%, net spend và tránh cảnh báo trùng. | E16: Phạm Nguyễn Tuấn Kiệt | F16: Võ Trịnh Quốc Huy | G16: P1 | H16: Done | I16: S1 | J16: 46314 | K16: 46320 | L16: 100 | M16: LEAD-02,DB-01 | N16: docs/api-budgets.md | O16: branch feature/plan-tuan-kiet — docs/api-budgets.md (2026-10-18) | P16: Tests FR05 có phần logic; UI chưa chắc nối API.
A17: PLAN-02 | B17: Ngân sách & tài sản | C17: Chốt mô hình khoản vay & mục tiêu | D17: Viết rule principal/interest, khoản đi vay/cho vay, gắn mục tiêu tiết kiệm; phân biệt asset/liability; design API. | E17: Phạm Nguyễn Tuấn Kiệt | F17: Nguyễn Thành Trung | G17: P1 | H17: Done | I17: S1 | J17: 46314 | K17: 46320 | L17: 100 | M17: DB-02 | N17: docs/finance-rules.md | O17: branch feature/plan-tuan-kiet — docs/finance-rules.md (2026-10-18) | P17: Khoản vay và mục tiêu đang có giao diện mock.
A18: QA-01 | B18: Kiểm thử & nghiệm thu | C18: Thiết lập checklist build/test baseline | D18: Kiểm `CHAY_SE.bat`, `/api/health`, backend PHP test, browser console; ghi kết quả baseline, không mặc định 36/36 PASS. | E18: Võ Trịnh Quốc Huy | F18: Nguyễn Thành Trung | G18: P1 | H18: To Do | I18: S1 | J18: 46314 | K18: 46320 | L18: 0 | M18: LEAD-01 | N18: docs/test-baseline.md | P18: README chỉ nêu kỳ vọng 36 PASSED.
A19: TX-04 | B19: Ví & giao dịch | C19: Thu/chi: form và POST vào ledger | D19: Form validation >0, category thuộc user; POST thành bút toán kép; ví cập nhật; reload dữ liệu vẫn còn. | E19: Võ Văn Khôi Nguyên | F19: Võ Trịnh Quốc Huy | G19: P1 | H19: To Do | I19: S2 | J19: 46321 | K19: 46327 | L19: 0 | M19: TX-02,TX-03,DB-04 | N19: source/frontend/js/app/forms.js; source/backend/ | P19: LedgerService đã được kiểm thử độc lập.
A20: TX-05 | B20: Ví & giao dịch | C20: Chuyển ví và số dư nhất quán | D20: Không chuyển cùng ví/không vượt số dư; debit/credit cả hai ví nguyên tử; không tính vào Thu/Chi. | E20: Võ Văn Khôi Nguyên | F20: Võ Trịnh Quốc Huy | G20: P1 | H20: To Do | I20: S2 | J20: 46321 | K20: 46327 | L20: 0 | M20: TX-04 | N20: source/frontend/js/app/pages.js; source/backend/ | P20: FR03 có test transfer/reversal.
A21: TX-06 | B21: Ví & giao dịch | C21: Lịch sử giao dịch, tìm kiếm và lọc | D21: Trang Giao dịch lấy API theo user, filter loại/ngày/từ khóa, empty/error/loading, không sử dụng fixture. | E21: Võ Văn Khôi Nguyên | F21: Võ Trịnh Quốc Huy | G21: P1 | H21: To Do | I21: S2 | J21: 46321 | K21: 46327 | L21: 0 | M21: TX-04 | N21: source/frontend/js/app/pages.js; source/frontend/js/app/main.js | P21: UI hiện lọc JS trên fixtures.
A22: TX-07 | B22: Ví & giao dịch | C22: Giao dịch nháp/đảo bút toán | D22: Cho chuyển DRAFT→POSTED; giao dịch POSTED chỉ đảo (reversal), không xóa vật lý; idempotency ngăn ghi đôi. | E22: Võ Văn Khôi Nguyên | F22: Võ Trịnh Quốc Huy | G22: P1 | H22: To Do | I22: S2 | J22: 46321 | K22: 46327 | L22: 0 | M22: TX-04 | N22: source/backend/; source/frontend/js/app/forms.js | P22: FR03 đã có test reversal/idempotency.
A23: TX-08 | B23: Ví & giao dịch | C23: Tỷ giá snapshot và nhiều tiền tệ | D23: Mỗi giao dịch ngoại tệ lưu snapshot rate, tính amount_base; báo lỗi nếu thiếu tỷ giá; không tự lấy FX giả làm live. | E23: Võ Văn Khôi Nguyên | F23: Nguyễn Thành Trung | G23: P2 | H23: To Do | I23: S2 | J23: 46321 | K23: 46327 | L23: 0 | M23: TX-04,DB-03 | N23: source/backend/; source/frontend/js/app/pages.js | P23: FR04 có test SQLite.
A24: TX-09 | B24: Ví & giao dịch | C24: Định kỳ: CRUD + worker thực tế | D24: Tạo lịch, pause/resume, worker 1 lần/kỳ; xử lý ngày 31→cuối tháng; AUTO_POST vs DRAFT_REMINDER. | E24: Võ Văn Khôi Nguyên | F24: Võ Trịnh Quốc Huy | G24: P1 | H24: To Do | I24: S2 | J24: 46321 | K24: 46327 | L24: 0 | M24: TX-04,DB-04 | N24: source/backend/; source/frontend/js/app/pages.js | P24: FR06 có test cho worker.
A25: DB-05 | B25: Database & tài liệu | C25: Migration cho tính năng còn thiếu | D25: Viết migration tăng dần IF/guard phù hợp MySQL, lưu version, có kế hoạch rollback; cấm DROP bảng đang dùng. | E25: Nguyễn Thành Trung | F25: Võ Trịnh Quốc Huy | G25: P1 | H25: To Do | I25: S2 | J25: 46321 | K25: 46327 | L25: 0 | M25: DB-02,DB-03 | N25: source/database/00x_*.sql | P25: Migration chỉ thêm nếu schema gốc chưa có.
A26: DB-06 | B26: Database & tài liệu | C26: Kiểm tra hiệu năng index và truy vấn | D26: EXPLAIN query lịch sử theo user/date/wallet/category, index phù hợp; không quét dữ liệu mọi user. | E26: Nguyễn Thành Trung | F26: Võ Văn Khôi Nguyên | G26: P2 | H26: To Do | I26: S2 | J26: 46321 | K26: 46327 | L26: 0 | M26: TX-06,DB-05 | N26: docs/db-performance.md | P26: Kiểm thử trên MySQL 3307 riêng SE.
A27: DB-07 | B27: Database & tài liệu | C27: Đồng bộ MySQL và bộ test SQLite | D27: Đối chiếu schema/test fixture, constraints, nullable; test SQLite không thay thế integration test MySQL. | E27: Nguyễn Thành Trung | F27: Võ Trịnh Quốc Huy | G27: P1 | H27: To Do | I27: S2 | J27: 46321 | K27: 46327 | L27: 0 | M27: DB-05 | N27: docs/db-test-parity.md; source/backend/tests/ | P27: Tránh lệch hành vi 2 DB.
A28: PLAN-03 | B28: Ngân sách & tài sản | C28: Ngân sách theo danh mục/kỳ | D28: CRUD budget theo user+category+month; tính chi tiêu ròng, không tính chuyển ví hay trả nợ gốc. | E28: Phạm Nguyễn Tuấn Kiệt | F28: Nguyễn Thành Trung | G28: P1 | H28: Done | I28: S2 | J28: 46321 | K28: 46327 | L28: 100 | M28: PLAN-01,TX-04 | N28: source/backend/; source/frontend/js/app/pages.js | O28: branch feature/plan-tuan-kiet — BudgetDAO/BudgetService + live-pages.js + run_tests.php (54/54 PASS) | P28: Backend BudgetService đã được test ở FR05.
A29: PLAN-04 | B29: Ngân sách & tài sản | C29: Cảnh báo 80% / 100% chính xác | D29: UI lấy % từ dữ liệu thực; backend sinh một thông báo/loại/ngưỡng/kỳ; không tự chặn chi tiêu. | E29: Phạm Nguyễn Tuấn Kiệt | F29: Võ Văn Khôi Nguyên | G29: P1 | H29: Done | I29: S2 | J29: 46321 | K29: 46327 | L29: 100 | M29: PLAN-03,TX-04 | N29: source/backend/; source/frontend/js/app/pages.js | O29: branch feature/plan-tuan-kiet — BR08 80%/100% + jump-over-yellow dedup + UI KPI/progress (54/54 PASS) | P29: Rule hiển thị sẵn trên budget UI.
A30: PLAN-05 | B30: Ngân sách & tài sản | C30: Trung tâm thông báo từ backend | D30: Xem/chưa xem; thông báo ngân sách/nhắc nợ; phân tách của user; không chèn notification demo vào kết quả thật. | E30: Phạm Nguyễn Tuấn Kiệt | F30: Võ Trịnh Quốc Huy | G30: P2 | H30: Done | I30: S2 | J30: 46321 | K30: 46327 | L30: 100 | M30: PLAN-04,DB-05 | N30: source/backend/; source/frontend/js/app/pages.js | O30: branch feature/plan-tuan-kiet — NotificationController/Service/DAO + UI filter/read-all (54/54 PASS) | P30: notificationsPage còn fixture.
A31: LEAD-06 | B31: Tích hợp & bảo mật | C31: Chuẩn hóa frontend API state dùng chung | D31: Dịch vụ fetch có CSRF/session nếu cần, loading/error/empty; các module không tự hardcode API base hay secret. | E31: Võ Trịnh Quốc Huy | F31: Võ Văn Khôi Nguyên | G31: P1 | H31: To Do | I31: S2 | J31: 46321 | K31: 46327 | L31: 0 | M31: LEAD-02,TX-01 | N31: source/frontend/js/services/; source/frontend/js/app/main.js | P31: Tránh sửa chồng `main.js`.
A32: LEAD-07 | B32: Tích hợp & bảo mật | C32: Kiểm tra an toàn input và quyền sở hữu | D32: Prepared statements, validate money/date, HTML escaping, quyền userId từ session; test IDOR đổi id của user khác. | E32: Võ Trịnh Quốc Huy | F32: Nguyễn Thành Trung | G32: P1 | H32: To Do | I32: S2 | J32: 46321 | K32: 46327 | L32: 0 | M32: TX-04,PLAN-03 | N32: source/backend/; docs/security-tests.md | P32: Bảo mật dữ liệu tài chính là P1.
A33: PLAN-06 | B33: Ngân sách & tài sản | C33: Mục tiêu tiết kiệm: CRUD/tiến độ | D33: Tạo mục tiêu target/deadline, phân bổ/hoàn trả, hoàn thành/hủy; phân bổ chỉ earmark không làm tăng net worth. | E33: Phạm Nguyễn Tuấn Kiệt | F33: Nguyễn Thành Trung | G33: P1 | H33: To Do | I33: S3 | J33: 46328 | K33: 46334 | L33: 0 | M33: PLAN-02,DB-05 | N33: source/backend/; source/frontend/js/app/pages.js | P33: UI goals có sẵn dạng demo.
A34: PLAN-07 | B34: Ngân sách & tài sản | C34: Vay/nợ: tạo khoản và lịch trả | D34: Phân biệt đi vay/cho vay, kỳ hạn, lãi/phí, due date, trả gốc; không ghi nhận vay là income. | E34: Phạm Nguyễn Tuấn Kiệt | F34: Nguyễn Thành Trung | G34: P1 | H34: To Do | I34: S3 | J34: 46328 | K34: 46334 | L34: 0 | M34: PLAN-02,DB-05,TX-04 | N34: source/backend/; source/frontend/js/app/pages.js | P34: UI loans có sẵn dạng demo.
A35: PLAN-08 | B35: Ngân sách & tài sản | C35: Ghi trả nợ/nhắc hạn an toàn | D35: Tách principal làm giảm liability và ví; interest/fees là expense; cảnh báo trước hạn; chống trả nợ 2 lần. | E35: Phạm Nguyễn Tuấn Kiệt | F35: Võ Văn Khôi Nguyên | G35: P1 | H35: To Do | I35: S3 | J35: 46328 | K35: 46334 | L35: 0 | M35: PLAN-07,PLAN-05 | N35: source/backend/; source/frontend/js/app/pages.js | P35: Rule đang được mô tả trên trang vay.
A36: PLAN-09 | B36: Ngân sách & tài sản | C36: Tài sản vàng: lô, định giá, snapshot | D36: Thêm/sửa asset vàng, số lượng, unit, valuation history; không lấy giá tĩnh hiện trên UI làm giá thị trường thực. | E36: Phạm Nguyễn Tuấn Kiệt | F36: Nguyễn Thành Trung | G36: P2 | H36: To Do | I36: S3 | J36: 46328 | K36: 46334 | L36: 0 | M36: DB-05,PLAN-02 | N36: source/backend/; source/frontend/js/app/pages.js | P36: goldPage sử dụng fixture.
A37: PLAN-10 | B37: Ngân sách & tài sản | C37: Net worth, balance sheet thật | D37: Net worth = assets - liabilities; exclude mục tiêu ghi nhãn kép; số liệu cùng thời điểm, filter kỳ, snapshot lịch sử. | E37: Phạm Nguyễn Tuấn Kiệt | F37: Võ Trịnh Quốc Huy | G37: P1 | H37: To Do | I37: S3 | J37: 46328 | K37: 46334 | L37: 0 | M37: PLAN-07,PLAN-09,TX-06 | N37: source/backend/; source/frontend/js/app/pages.js | P37: overview đang có KPI giá trị hardcoded.
A38: PLAN-11 | B38: Ngân sách & tài sản | C38: Báo cáo thu–chi và saving rate | D38: Dữ liệu từ ledger; Income-Expense (loại chuyển ví/gốc nợ); rate N/A khi income≤0; chart lấy theo kỳ. | E38: Phạm Nguyễn Tuấn Kiệt | F38: Võ Trịnh Quốc Huy | G38: P1 | H38: To Do | I38: S3 | J38: 46328 | K38: 46334 | L38: 0 | M38: PLAN-10,TX-06 | N38: source/backend/; source/frontend/js/app/pages.js | P38: reportPage tự ghi chú chưa lấy MySQL.
A39: TX-10 | B39: Ví & giao dịch | C39: Kết nối UI định kỳ & bỏ mock | D39: Danh sách định kỳ từ API, nút pause/delete chạy thật; refresh giữ trạng thái; rõ ngày tới hạn và mode. | E39: Võ Văn Khôi Nguyên | F39: Phạm Nguyễn Tuấn Kiệt | G39: P1 | H39: To Do | I39: S3 | J39: 46328 | K39: 46334 | L39: 0 | M39: TX-09,LEAD-06 | N39: source/frontend/js/app/pages.js; source/frontend/js/data/fixtures.js | P39: Bỏ fixture đúng module, không xóa chung bừa bãi.
A40: TX-11 | B40: Ví & giao dịch | C40: Đối soát ví với bút toán thật | D40: Tính sum ledger entries so cached_balance, phát hiện chênh; tuyệt đối không hiển thị 'Mô phỏng khớp' như kết quả thực. | E40: Võ Văn Khôi Nguyên | F40: Võ Trịnh Quốc Huy | G40: P1 | H40: To Do | I40: S3 | J40: 46328 | K40: 46334 | L40: 0 | M40: TX-07,DB-06 | N40: source/backend/; source/frontend/js/app/pages.js | P40: reconciliationPage đang mô phỏng.
...

Sheet TongQuan
A1: WEALTHFLOW | DASHBOARD & MỐC TIẾN ĐỘ
A2: Đồ án CNPM — 4 thành viên / 3 người lập trình / 1 người Database & tài liệu. Trạng thái bên dưới tự cập nhật từ sheet PhanCong.
A4: TỔNG CÔNG VIỆC | C4: CHƯA LÀM | E4: ĐANG THỰC HIỆN | G4: CHỜ REVIEW | I4: HOÀN THÀNH | K4: TIẾN ĐỘ CHUNG
A5: =COUNTA(PhanCong!$A$4:$A$57) | C5: =COUNTIF(PhanCong!$H$4:$H$57,"To Do") | E5: =COUNTIF(PhanCong!$H$4:$H$57,"In Progress")+COUNTIF(PhanCong!$H$4:$H$57,"Blocked") | G5: =COUNTIF(PhanCong!$H$4:$H$57,"In Review") | I5: =COUNTIF(PhanCong!$H$4:$H$57,"Done") | K5: =IFERROR(AVERAGE(PhanCong!$L$4:$L$57)/100,0)
A8: TIẾN ĐỘ THEO PHÂN HỆ
A9: STT | B9: Phân hệ | C9: Số task | D9: Done | E9: Đang làm | F9: Chưa làm | G9: Hoàn tất (%)
A10: 1 | B10: Tích hợp & bảo mật | C10: =COUNTIF(PhanCong!$B$4:$B$57,B10) | D10: =COUNTIFS(PhanCong!$B$4:$B$57,B10,PhanCong!$H$4:$H$57,"Done") | E10: =COUNTIFS(PhanCong!$B$4:$B$57,B10,PhanCong!$H$4:$H$57,"In Progress")+COUNTIFS(PhanCong!$B$4:$B$57,B10,PhanCong!$H$4:$H$57,"Blocked")+COUNTIFS(PhanCong!$B$4:$B$57,B10,PhanCong!$H$4:$H$57,"In Review") | F10: =COUNTIFS(PhanCong!$B$4:$B$57,B10,PhanCong!$H$4:$H$57,"To Do") | G10: =IFERROR(AVERAGEIF(PhanCong!$B$4:$B$57,B10,PhanCong!$L$4:$L$57)/100,0)
A11: 2 | B11: Ví & giao dịch | C11: =COUNTIF(PhanCong!$B$4:$B$57,B11) | D11: =COUNTIFS(PhanCong!$B$4:$B$57,B11,PhanCong!$H$4:$H$57,"Done") | E11: =COUNTIFS(PhanCong!$B$4:$B$57,B11,PhanCong!$H$4:$H$57,"In Progress")+COUNTIFS(PhanCong!$B$4:$B$57,B11,PhanCong!$H$4:$H$57,"Blocked")+COUNTIFS(PhanCong!$B$4:$B$57,B11,PhanCong!$H$4:$H$57,"In Review") | F11: =COUNTIFS(PhanCong!$B$4:$B$57,B11,PhanCong!$H$4:$H$57,"To Do") | G11: =IFERROR(AVERAGEIF(PhanCong!$B$4:$B$57,B11,PhanCong!$L$4:$L$57)/100,0)
A12: 3 | B12: Ngân sách & tài sản | C12: =COUNTIF(PhanCong!$B$4:$B$57,B12) | D12: =COUNTIFS(PhanCong!$B$4:$B$57,B12,PhanCong!$H$4:$H$57,"Done") | E12: =COUNTIFS(PhanCong!$B$4:$B$57,B12,PhanCong!$H$4:$H$57,"In Progress")+COUNTIFS(PhanCong!$B$4:$B$57,B12,PhanCong!$H$4:$H$57,"Blocked")+COUNTIFS(PhanCong!$B$4:$B$57,B12,PhanCong!$H$4:$H$57,"In Review") | F12: =COUNTIFS(PhanCong!$B$4:$B$57,B12,PhanCong!$H$4:$H$57,"To Do") | G12: =IFERROR(AVERAGEIF(PhanCong!$B$4:$B$57,B12,PhanCong!$L$4:$L$57)/100,0)
A13: 4 | B13: Database & tài liệu | C13: =COUNTIF(PhanCong!$B$4:$B$57,B13) | D13: =COUNTIFS(PhanCong!$B$4:$B$57,B13,PhanCong!$H$4:$H$57,"Done") | E13: =COUNTIFS(PhanCong!$B$4:$B$57,B13,PhanCong!$H$4:$H$57,"In Progress")+COUNTIFS(PhanCong!$B$4:$B$57,B13,PhanCong!$H$4:$H$57,"Blocked")+COUNTIFS(PhanCong!$B$4:$B$57,B13,PhanCong!$H$4:$H$57,"In Review") | F13: =COUNTIFS(PhanCong!$B$4:$B$57,B13,PhanCong!$H$4:$H$57,"To Do") | G13: =IFERROR(AVERAGEIF(PhanCong!$B$4:$B$57,B13,PhanCong!$L$4:$L$57)/100,0)
A14: 5 | B14: Kiểm thử & nghiệm thu | C14: =COUNTIF(PhanCong!$B$4:$B$57,B14) | D14: =COUNTIFS(PhanCong!$B$4:$B$57,B14,PhanCong!$H$4:$H$57,"Done") | E14: =COUNTIFS(PhanCong!$B$4:$B$57,B14,PhanCong!$H$4:$H$57,"In Progress")+COUNTIFS(PhanCong!$B$4:$B$57,B14,PhanCong!$H$4:$H$57,"Blocked")+COUNTIFS(PhanCong!$B$4:$B$57,B14,PhanCong!$H$4:$H$57,"In Review") | F14: =COUNTIFS(PhanCong!$B$4:$B$57,B14,PhanCong!$H$4:$H$57,"To Do") | G14: =IFERROR(AVERAGEIF(PhanCong!$B$4:$B$57,B14,PhanCong!$L$4:$L$57)/100,0)
A17: KHỐI LƯỢNG CÔNG VIỆC THEO THÀNH VIÊN
A18: STT | B18: Thành viên | C18: Số task | D18: Done | E18: Đang làm | F18: Còn lại | G18: Hoàn tất (%)
A19: 1 | B19: Võ Trịnh Quốc Huy | C19: =COUNTIF(PhanCong!$E$4:$E$57,B19) | D19: =COUNTIFS(PhanCong!$E$4:$E$57,B19,PhanCong!$H$4:$H$57,"Done") | E19: =COUNTIFS(PhanCong!$E$4:$E$57,B19,PhanCong!$H$4:$H$57,"In Progress")+COUNTIFS(PhanCong!$E$4:$E$57,B19,PhanCong!$H$4:$H$57,"In Review") | F19: =C19-D19-E19 | G19: =IFERROR(AVERAGEIF(PhanCong!$E$4:$E$57,B19,PhanCong!$L$4:$L$57)/100,0)
A20: 2 | B20: Võ Văn Khôi Nguyên | C20: =COUNTIF(PhanCong!$E$4:$E$57,B20) | D20: =COUNTIFS(PhanCong!$E$4:$E$57,B20,PhanCong!$H$4:$H$57,"Done") | E20: =COUNTIFS(PhanCong!$E$4:$E$57,B20,PhanCong!$H$4:$H$57,"In Progress")+COUNTIFS(PhanCong!$E$4:$E$57,B20,PhanCong!$H$4:$H$57,"In Review") | F20: =C20-D20-E20 | G20: =IFERROR(AVERAGEIF(PhanCong!$E$4:$E$57,B20,PhanCong!$L$4:$L$57)/100,0)
A21: 3 | B21: Phạm Nguyễn Tuấn Kiệt | C21: =COUNTIF(PhanCong!$E$4:$E$57,B21) | D21: =COUNTIFS(PhanCong!$E$4:$E$57,B21,PhanCong!$H$4:$H$57,"Done") | E21: =COUNTIFS(PhanCong!$E$4:$E$57,B21,PhanCong!$H$4:$H$57,"In Progress")+COUNTIFS(PhanCong!$E$4:$E$57,B21,PhanCong!$H$4:$H$57,"In Review") | F21: =C21-D21-E21 | G21: =IFERROR(AVERAGEIF(PhanCong!$E$4:$E$57,B21,PhanCong!$L$4:$L$57)/100,0)
A22: 4 | B22: Nguyễn Thành Trung | C22: =COUNTIF(PhanCong!$E$4:$E$57,B22) | D22: =COUNTIFS(PhanCong!$E$4:$E$57,B22,PhanCong!$H$4:$H$57,"Done") | E22: =COUNTIFS(PhanCong!$E$4:$E$57,B22,PhanCong!$H$4:$H$57,"In Progress")+COUNTIFS(PhanCong!$E$4:$E$57,B22,PhanCong!$H$4:$H$57,"In Review") | F22: =C22-D22-E22 | G22: =IFERROR(AVERAGEIF(PhanCong!$E$4:$E$57,B22,PhanCong!$L$4:$L$57)/100,0)
A25: 4 SPRINT — LỊCH DỰ KIẾN, CÓ THỂ ĐIỀU CHỈNH THEO DEADLINE CỦA GIẢNG VIÊN
A26: Sprint | B26: Khoảng thời gian | C26: Trọng tâm | D26: Đầu ra nghiệm thu | E26: Điều kiện chuyển giai đoạn
A27: S1 | B27: 19–25/10/2026 | C27: Baseline, ERD, API contract, auth | D27: Tài liệu kiến trúc, seed và chạy xác thực được | E27: Có ERD / API contract / test baseline
A28: S2 | B28: 26/10–01/11/2026 | C28: Thu/chi-ví-ngân sách-định kỳ nối MySQL | D28: Luồng E2E wallets→transactions→budget/recurring | E28: Reload vẫn còn dữ liệu, không giả mock
A29: S3 | B29: 02–08/11/2026 | C29: Tiết kiệm, vay/nợ, vàng, net worth, báo cáo | D29: Dashboard + báo cáo tính từ sổ cái thật | E29: SQL và chỉ số UI đối chiếu đúng
A30: S4 | B30: 09–15/11/2026 | C30: QA, bảo mật, tài liệu, demo & release | D30: Test report, ERD/SRS, video/script demo, release | E30: Không còn lỗi P1, 2 users phân quyền đúng
A33: NHỮNG ĐIỂM ĐÃ XÁC NHẬN TỪ REPOSITORY
A34: Backend có kiểm thử FR03–FR06 (ledger, FX, budget, recurring); UI nhiều chức năng vẫn lấy dữ liệu fixtures. Đây là baseline, KHÔNG phải khẳng định toàn bộ app đã hoàn thiện.
A35: Môi trường SE: PHP local 8080 + MySQL riêng 3307 (C:\xampp\se-instance); tránh tác động dự án LTW dùng MySQL 3306.
A37: Repo: | B37: https://github.com/huytothevoz/SE---Microfinance-Personal-Wealth-Expense-Tracker
A38: Nguồn: | B38: https://github.com/huytothevoz/SE---Microfinance-Personal-Wealth-Expense-Tracker/blob/main/README.md

Sheet VaiTro_RACI
A1: WEALTHFLOW | VAI TRÒ, CAM KẾT & RACI
A2: R=Thực hiện; A=chịu trách nhiệm cuối cùng; C=tham vấn; I=được thông báo. Một hạng mục nên có một người Accountable.
A4: DANH SÁCH THÀNH VIÊN
A5: STT | B5: Họ tên | C5: Vai trò | D5: Mảng chịu trách nhiệm | E5: Nguyên tắc bàn giao | F5: Số task
A6: 1 | B6: Võ Trịnh Quốc Huy | C6: Team Leader / Fullstack | D6: Auth, kiến trúc, tích hợp, bảo mật, dashboard, merge & release | E6: Giữ quyền review/merge main; review PHP/JS/SQL liên module | F6: 14
A7: 2 | B7: Võ Văn Khôi Nguyên | C7: Developer / Core Finance | D7: Wallets, categories, ledger UI/API, transfer, recurring, export, reconciliation | E7: Sở hữu nghiệp vụ FR03/FR04/FR06 và phần lớn file giao dịch | F7: 14
A8: 3 | B8: Phạm Nguyễn Tuấn Kiệt | C8: Developer / Financial Planning | D8: Budget, notifications, savings, loans, gold, net worth, reporting | E8: Sở hữu nghiệp vụ FR05 và mở rộng tài sản / vay | F8: 13
A9: 4 | B9: Nguyễn Thành Trung | C9: Database & Documentation | D9: Schema/ERD, migrations, SQL seed, backup, DB tests, SRS/UML, báo cáo | E9: Không nhận lập trình nghiệp vụ web chính; SQL và tài liệu là trách nhiệm chủ đạo | F9: 13
A12: MA TRẬN TRÁCH NHIỆM
A13: STT | B13: Hạng mục | C13: Huy – Leader | D13: Khôi Nguyên | E13: Tuấn Kiệt | F13: Thành Trung
A14: 1 | B14: Chốt kiến trúc & quy chuẩn Git | C14: A/R | D14: C | E14: C | F14: C
A15: 2 | B15: Bảo mật/OTP/Session, Admin | C15: A/R | D15: I | E15: C | F15: C
A16: 3 | B16: Ví, danh mục, ledger, chuyển ví | C16: A | D16: R | E16: C | F16: C
A17: 4 | B17: Giao dịch định kỳ, FX, đối soát | C17: A | D17: R | E17: C | F17: C
A18: 5 | B18: Ngân sách & thông báo | C18: A | D18: C | E18: R | F18: C
A19: 6 | B19: Mục tiêu tiết kiệm | C19: A | D19: C | E19: R | F19: C
A20: 7 | B20: Khoản vay và lịch trả | C20: A | D20: C | E20: R | F20: C
A21: 8 | B21: Tài sản vàng & Net Worth | C21: A | D21: C | E21: R | F21: C
A22: 9 | B22: Dashboard tổng quan & tích hợp API | C22: A/R | D22: C | E22: R | F22: C
A23: 10 | B23: Thiết kế ERD, database migration, index | C23: A | D23: C | E23: C | F23: R
A24: 11 | B24: Data dictionary, SQL seed, backup/restore | C24: A | D24: C | E24: C | F24: R
A25: 12 | B25: Kiểm thử từng module và test case | C25: A | D25: R | E25: R | F25: C
... A27: 14 | B27: Code review, merge, release, demo cuối | C27: A/R | D27: C | E27: C | F27: R
A30: QUY ĐỊNH RANH GIỚI PHẦN VIỆC
A31: Một task = một owner | B31: Người được giao ở cột Owner chịu trách nhiệm tạo PR + test + cập nhật tiến độ, reviewer không tự nhận phần trăm.
A32: Trung phụ trách Database | B32: Trung viết/kiểm thử SQL, migration, data dictionary, ERD và hỗ trợ SRS; dev PHP kết nối theo contract, tránh 3 người tự sửa schema.
A33: Không sửa chồng file chung | B33: pages.js và main.js cần phân tách module hoặc chia nhánh với thứ tự merge do Huy thống nhất; mỗi PR nhỏ để tránh conflict.
A34: Review PHP / SQL | B34: Huy review code logic; Trung review migration và ERD; dev liên quan kiểm tra API có đúng contract.
A35: Không tự nhận task Done | B35: Phải có link PR/commit, kiểm thử local thực tế trên MySQL 3307, ảnh hoặc testcase và đã merge.

Sheet YeuCau
A1: WEALTHFLOW | ĐẶC TẢ CHỨC NĂNG (SRS RÚT GỌN)
A2: Phân biệt mức độ hiện có trong Git với trạng thái đã kiểm thử. Không xem giao diện mock là tính năng E2E.
A3: Mã | B3: Module | C3: Mô tả phạm vi | D3: Input chính | E3: Output/giá trị | F3: Quy tắc nghiệp vụ / Acceptance criteria | G3: Code owner | H3: Trạng thái khảo sát Git | I3: Ưu tiên
A4: FR01 | B4: Đăng ký/đăng nhập/OTP | C4: Tạo user, login, session, reset bằng OTP | D4: Email, password, fullName, OTP | E4: Phiên hợp lệ, đổi mật khẩu, bảo vệ tuyến | F4: Không trùng email; OTP 10 phút/5 lần theo README; không log secrets | G4: Võ Trịnh Quốc Huy | H4: README nêu quy trình; chưa chạy local | I4: P1
A5: FR02 | B5: Hồ sơ cá nhân | C5: Xem và cập nhật tên, ngôn ngữ, tiền cơ sở, theme | D5: Profile settings | E5: Persist cài đặt theo user | F5: Validate, riêng tư; đổi base currency cần có chính sách | G5: Võ Trịnh Quốc Huy | H5: Có UI settings, cần test API | I5: P2
A6: FR03 | B6: Thu chi & sổ cái | C6: Thu/chi, transfer, draft, reversal, idempotency | D6: wallet/category/amount/date/currency | E6: 2 bút toán cân; số dư cập nhật | F6: Posted không xóa; debit=credit; không chuyển cùng ví | G6: Võ Văn Khôi Nguyên | H6: Có backend test; UI dùng fixtures | I6: P1
A7: FR04 | B7: Đa tiền tệ | C7: Ghi nhận giao dịch ngoại tệ snapshot FX | D7: Currency, FX rate | E7: Amount base nhất quán | F7: Giữ tỷ giá theo thời điểm ghi sổ; không dựa vào FX live không nguồn | G7: Võ Văn Khôi Nguyên | H7: Có backend test FR04 | I7: P2
A8: FR05 | B8: Ngân sách | C8: Hạn mức theo danh mục/kỳ và cảnh báo | D8: Month, category, limit | E8: Tỷ lệ đã dùng, thông báo ngưỡng | F8: Chi tiêu ròng; 80% vàng, 100% đỏ, không lặp cảnh báo | G8: Phạm Nguyễn Tuấn Kiệt | H8: Backend test FR05; UI demo | I8: P1
A9: FR06 | B9: Định kỳ | C9: Lịch tạo draft/tự ghi sổ | D9: DayOfMonth, amount, mode, wallet | E9: Tạo một kỳ duy nhất và next due | F9: Ngày 31 kẹp cuối tháng; idempotent mỗi kỳ | G9: Võ Văn Khôi Nguyên | H9: Backend test FR06; UI demo | I9: P1
A10: FR07 | B10: Ví | C10: Tạo/sửa/lưu trữ ví nhiều loại | D10: Name, currency, opening balance | E10: Wallet list và balance từ DB | F10: Không lưu trữ khi còn dư nợ liên quan / định kỳ đang dùng | G10: Võ Văn Khôi Nguyên | H10: UI mock, repository có trong test | I10: P1
A11: FR08 | B11: Danh mục | C11: Danh mục người dùng và danh mục mẫu | D11: Type,name,isActive | E11: Dùng chung filter/budget | F11: Không xóa vật lý danh mục có ledger | G11: Võ Văn Khôi Nguyên | H11: Có UI mock | I11: P1
A12: FR09 | B12: Mục tiêu tiết kiệm | C12: Tạo mục tiêu và phân bổ tiền | D12: Target, date, allocations | E12: Tiến độ tích lũy và lịch sử | F12: Earmark không làm tăng tổng tài sản | G12: Phạm Nguyễn Tuấn Kiệt | H12: UI mock, chưa xác nhận API | I12: P1
A13: FR10 | B13: Vay/cho vay | C13: Quản lý dư gốc, trả góp, lãi/phí | D13: Kind, principal, terms, payments | E13: Dư nợ và lịch sử, nhắc tới hạn | F13: Đi vay không phải thu nhập; gốc không là expense | G13: Phạm Nguyễn Tuấn Kiệt | H13: UI mock, chưa xác nhận API | I13: P1
A14: FR11 | B14: Tài sản vàng | C14: Quản lý số lượng, định giá, lịch sử | D14: Asset lot, quantity, unit, valuation | E14: Giá trị tài sản ngoài ví | F14: Ngày định giá rõ; không mặc định giá fixture là giá thật | G14: Phạm Nguyễn Tuấn Kiệt | H14: UI mock, chưa xác nhận API | I14: P2
... A21: NFR02 | B21: Tính chạy độc lập | C21: Không ảnh hưởng đồ án LTW trên XAMPP | D21: SE 8080+3307, LTW 8000+3306 | E21: Start/stop riêng SE an toàn | F21: Migration không DROP, không xóa htdocs/MySQL của LTW | G21: Võ Trịnh Quốc Huy | H21: Runner có trong README/HUONG_DAN | I21: P1

Sheet KienTruc_CSDL
A1: WEALTHFLOW | KIẾN TRÚC, DATA & QUY TẮC NGHIỆP VỤ
A2: Đặc tả dùng cho phân công và báo cáo; mọi tên bảng MỚI chỉ là gợi ý, cần xác nhận bằng SQL migration thực tế.
A4: SƠ ĐỒ 4 LỚP / LUỒNG DỮ LIỆU
A5: Lớp | B5: Công nghệ | C5: File / vị trí | D5: Trách nhiệm | E5: Owner | F5: Lưu ý
A6: 1. UI | B6: HTML/CSS/Vanilla JS | C6: source/frontend/js/landing/main.js; source/frontend/js/app/pages.js; forms.js; main.js | D6: Form & chart lấy API sau khi login | E6: Huy + Nguyên + Kiệt | F6: Không xử lý business logic quan trọng trong JS
A7: 2. Service | B7: Fetch + auth API | C7: source/frontend/js/services/auth-api.js; đề xuất thêm services/finance-api.js | D7: Request JSON, CSRF/session, loading/error/empty | E7: Huy xây chuẩn, 2 dev dùng chung | F7: Không hardcode token, base URL hoặc dùng fixtures làm thật
A8: 3. PHP | B8: Router, modules/services/repos | C8: source/backend/router.php; source/backend/src/Modules/... | D8: Validate, authorization, ledger, financial reports | E8: 3 dev code theo module | F8: Không tin userId do client tự gửi
A9: 4. Data | B9: MySQL instance độc lập | C9: source/database/001_initial_schema.sql & migration; C:\xampp\se-instance | D9: FK/transaction/index/seed | E9: Trung, review Huy | F9: MySQL SE 127.0.0.1:3307, tránh LTW 3306
A10: 5. Test | B10: Unit + E2E + tài liệu | C10: source/backend/tests/run_tests.php; docs/test-evidence/ | D10: SQLite unit + MySQL local integration | E10: Mỗi code owner + Trung | F10: 36 PASSED trong README là kỳ vọng, không phải kết quả đã chạy tại đây
A13: MÔ HÌNH DỮ LIỆU NGHIỆP VỤ — KIỂM TRA LẠI TÊN BẢNG TRONG REPO
A14: Entity (tên tham khảo) | B14: Mục đích | C14: Quan hệ | D14: Căn cứ hiện có | E14: Phụ trách | F14: Integrity rules
A15: users / auth-related | B15: User và phiên xác thực | C15: 1–N wallet, transaction, budget, loan... | D15: Kiểm tra thực tế | E15: Trung | F15: UserId là scope của tất cả truy vấn
A16: wallets | B16: Ví, loại, currency, cached_balance | C16: N–1 users | D16: Repository có trong test | E16: Trung/Nguyên | F16: Số dư phải có đường đối soát ledger
A17: categories | B17: Nhóm thu/chi và loại dữ liệu | C17: N–1 users, transaction | D17: Repository có trong test | E17: Trung/Nguyên | F17: Danh mục mặc định và cá nhân
A18: financial_transactions / ledger_entries | B18: Giao dịch + bút toán ghi sổ | C18: 1–N entry; N–1 user/wallet/category | D18: `financial_transactions` thấy trong test; kiểm tra tên entries | E18: Trung/Nguyên | F18: Double-entry và reversal, idempotency
A19: exchange_rates / snapshots | B19: Tỷ giá lưu theo thời điểm | C19: Dùng khi FX | D19: Cần xác nhận tên bảng | E19: Trung/Nguyên | F19: Amount_base giữ nguyên sau POST
A20: budgets / budget_alerts | B20: Giới hạn theo tháng, trạng thái cảnh báo | C20: N–1 user/category | D20: BudgetRepository có trong test | E20: Trung/Kiệt | F20: Unique user/category/month; tránh cảnh báo lặp
A21: recurring_* | B21: Lịch, kỳ chạy, next_due | C21: N–1 wallet/category/user | D21: RecurringRepository có trong test | E21: Trung/Nguyên | F21: 1 kỳ chỉ có 1 ghi sổ
A22: savings_goals / allocations | B22: Mục tiêu, phân bổ tiền | C22: N–1 users, wallet | D22: Đề xuất; xác nhận trước migration | E22: Trung/Kiệt | F22: Earmark không cộng tài sản 2 lần
A23: loans / loan_payments | B23: Khoản vay/cho vay, gốc lãi phí | C23: N–1 users | D23: Đề xuất; xác nhận trước migration | E23: Trung/Kiệt | F23: Principal khác Expense
A24: gold_assets / valuations | B24: Tài sản vàng và lần định giá | C24: N–1 users | D24: Đề xuất; xác nhận trước migration | E24: Trung/Kiệt | F24: Snapshot định giá theo ngày
A25: notifications / logs | B25: Thông báo, audit | C25: N–1 users | D25: NotificationService có trong test | E25: Trung/Kiệt/Huy | F25: Ownership + dedupe
A26: net_worth_snapshots | B26: Dữ liệu tài sản ròng theo kỳ | C26: N–1 users | D26: Đề xuất; xác nhận trước migration | E26: Trung/Kiệt | F26: Không tính chồng tiền mục tiêu
A29: QUY TẮC TÍNH TOÁN CẦN THỐNG NHẤT VỚI GIẢNG VIÊN
A30: Mã | B30: Quy tắc | C30: Tiêu chí nghiệm thu | D30: Liên quan
A31: BR01 | B31: Net Worth = Tổng tài sản − Tổng nợ phải trả | C31: Không cộng tiền đã phân bổ mục tiêu như tài sản mới | D31: FR12
A32: BR02 | B32: Net Cash Flow = Income − Expense | C32: Loại transfer, tiền vay nhận và trả nợ gốc khỏi thu nhập/chi phí | D32: FR03,FR13
A33: BR03 | B33: Saving Rate = (Income − Expense)/Income | C33: Income <= 0 => N/A; không chia 0 | D33: FR13
A34: BR04 | B34: Double-entry | C34: Tổng DebitBase = CreditBase trong một giao dịch Posted | D34: FR03
A35: BR05 | B35: Transfer | C35: Một ví giảm, ví kia tăng; không tạo Thu/Chi | D35: FR03
A36: BR06 | B36: Reversal | C36: Ghi bút toán đảo liên kết transaction cũ; không xóa Posted | D36: FR03
A37: BR07 | B37: Budget usage | C37: Net expense có loại trừ internal transfer/gốc nợ; 80/100% | D37: FR05
A38: BR08 | B38: Alert dedupe | C38: Mỗi ngưỡng loại YELLOW/RED chỉ một lần trong mỗi kỳ | D38: FR05,FR14
A39: BR09 | B39: Monthly clamp | C39: Ngày neo 31 chuyển sang ngày cuối tháng, phục hồi 31 khi đủ ngày | D39: FR06
A40: BR10 | B40: Loan principal | C40: Trả gốc làm giảm ví và khoản nợ; lãi/phí tính expense | D40: FR10
A41: BR11 | B41: FX snapshot | C41: Không dùng tỷ giá hiện tại để sửa amount_base của giao dịch đã Posted | D41: FR04
A42: BR12 | B42: Ownership | C42: WHERE user_id=current authenticated user trong mọi truy vấn tài chính | D42: NFR01

Sheet KiemThu
A1: WEALTHFLOW | TEST CASES & BẰNG CHỨNG NGHIỆM THU
A2: Test case cần có PASS/FAIL, ngày chạy, môi trường và link bằng chứng; để Not Run mặc định vì chưa thực thi trên máy nhóm.
A3: Test ID | B3: Liên kết FR | C3: Kịch bản | D3: Bước kiểm thử | E3: Kết quả mong đợi | F3: Thực hiện | G3: Người xác nhận | H3: Ưu tiên | I3: Kết quả | J3: Link minh chứng / ngày
A4: TC-01 | B4: FR01 | C4: Đăng ký user mới | D4: Nhập email hợp lệ + mật khẩu mạnh | E4: Tạo user đúng và không lộ secret | F4: Võ Trịnh Quốc Huy | G4: Nguyễn Thành Trung | H4: P1 | I4: Not Run
A5: TC-02 | B5: FR01 | C5: Trùng email / sai password | D5: Đăng ký trùng và login sai | E5: Từ chối đúng mã; không tạo bản ghi trùng | F5: Võ Trịnh Quốc Huy | G5: Nguyễn Thành Trung | H5: P1 | I5: Not Run
A6: TC-03 | B6: FR01 | C6: OTP hết hạn/vượt số lần | D6: Dùng OTP quá 10 phút hoặc nhập sai >5 | E6: Vô hiệu hóa OTP; không đổi mật khẩu | F6: Võ Trịnh Quốc Huy | G6: Nguyễn Thành Trung | H6: P1 | I6: Not Run
A7: TC-04 | B7: NFR01 | C7: Cách ly userId / IDOR | D7: User A dùng ID ví/giao dịch của User B | E7: 403/404; không đọc/sửa/xóa dữ liệu của B | F7: Võ Trịnh Quốc Huy | G7: Nguyễn Thành Trung | H7: P1 | I7: Not Run
A8: TC-05 | B8: FR07 | C8: Tạo ví và lưu trữ | D8: Tạo ví; lưu trữ khi balance>0 hoặc có recurring | E8: Chỉ lưu trữ khi thỏa điều kiện | F8: Võ Văn Khôi Nguyên | G8: Nguyễn Thành Trung | H8: P1 | I8: Not Run
A9: TC-06 | B9: FR03 | C9: Ghi thu/chi có ledger cân | D9: POST thu/chi từ 1 ví | E9: Sum debit=credit; số dư đúng, refresh còn | F9: Võ Văn Khôi Nguyên | G9: Nguyễn Thành Trung | H9: P1 | I9: Not Run
A10: TC-07 | B10: FR03 | C10: Chuyển ví không thành Thu/Chi | D10: Chuyển 500.000 giữa hai ví | E10: Ví nguồn -500k, đích +500k, income/expense không đổi | F10: Võ Văn Khôi Nguyên | G10: Võ Trịnh Quốc Huy | H10: P1 | I10: Not Run
A11: TC-08 | B11: FR03 | C11: Reversal thay vì xóa | D11: Đảo posted transaction | E11: Có transaction liên kết đảo; số dư được hoàn trả | F11: Võ Văn Khôi Nguyên | G11: Võ Trịnh Quốc Huy | H11: P1 | I11: Not Run
A12: TC-09 | B12: FR03 | C12: Idempotency tránh ghi đôi | D12: Gửi 2 request cùng idempotency key | E12: Chỉ một lần phát sinh bút toán | F12: Võ Văn Khôi Nguyên | G12: Võ Trịnh Quốc Huy | H12: P1 | I12: Not Run
A13: TC-10 | B13: FR04 | C13: Foreign exchange snapshot | D13: Ghi USD khi có rate, sau đó đổi rate | E13: Số amount_base lịch sử bất biến | F13: Võ Văn Khôi Nguyên | G13: Nguyễn Thành Trung | H13: P2 | I13: Not Run
A14: TC-11 | B14: FR08 | C14: Danh mục có giao dịch | D14: Lưu trữ/xóa danh mục đã dùng | E14: Không xóa khiến giao dịch mất FK | F14: Võ Văn Khôi Nguyên | G14: Nguyễn Thành Trung | H14: P1 | I14: Not Run
A15: TC-12 | B15: FR05 | C15: Ngưỡng ngân sách 80% / 100% | D15: Chi tiêu vượt lần lượt 80 và 100% | E15: Cảnh báo đúng 1 lần/ngưỡng/kỳ | F15: Phạm Nguyễn Tuấn Kiệt | G15: Võ Văn Khôi Nguyên | H15: P1 | I15: Pass | J15: 2026-10-18 — source/backend/tests/run_tests.php (TC-F05.02, TC-12.1, TC-12.2 PASS)
A16: TC-13 | B16: FR05 | C16: Loại transfer/gốc nợ khỏi budget | D16: Chuyển ví/trả gốc và kiểm tra budget | E16: Net expense không bị cộng sai | F16: Phạm Nguyễn Tuấn Kiệt | G16: Nguyễn Thành Trung | H16: P1 | I16: Pass | J16: 2026-10-18 — source/backend/tests/run_tests.php (TC-13 BR07 PASS)
A17: TC-14 | B17: FR06 | C17: Ngày định kỳ 31 → 28 → 31 | D17: Tạo lịch ngày 31 qua tháng 2, tháng 3 | E17: Next_due chính xác | F17: Võ Văn Khôi Nguyên | G17: Nguyễn Thành Trung | H17: P1 | I17: Not Run
A18: TC-15 | B18: FR06 | C18: Worker chạy lại trong cùng kỳ | D18: Chạy recurring worker 2 lần | E18: Không tạo giao dịch trùng kỳ | F18: Võ Văn Khôi Nguyên | G18: Võ Trịnh Quốc Huy | H18: P1 | I18: Not Run
A19: TC-16 | B19: FR09 | C19: Phân bổ tiết kiệm | D19: Phân bổ 1 triệu vào một goal | E19: Goal tăng; tổng Net Worth không tăng | F19: Phạm Nguyễn Tuấn Kiệt | G19: Nguyễn Thành Trung | H19: P1 | I19: Not Run
A20: TC-17 | B20: FR10 | C20: Vay 5tr → trả gốc 1tr, lãi 50k | D20: Ghi nhận dòng tiền nhận vay và trả nợ | E20: Dư nợ còn 4tr, expense chỉ có 50k tiền lãi | F20: Phạm Nguyễn Tuấn Kiệt | G20: Nguyễn Thành Trung | H20: P1 | I20: Not Run
A21: TC-18 | B21: FR11 | C21: Định giá vàng theo ngày | D21: Tạo asset và hai valuation snapshots | E21: Chart hiển thị giá trị đúng theo từng ngày | F21: Phạm Nguyễn Tuấn Kiệt | G21: Nguyễn Thành Trung | H21: P2 | I21: Not Run
A22: TC-19 | B22: FR12 | C22: Net Worth đúng khi có nợ | D22: Tạo ví/gold/loan và tính lại SQL | E22: Assets–Liabilities = UI và API | F22: Phạm Nguyễn Tuấn Kiệt | G22: Võ Trịnh Quốc Huy | H22: P1 | I22: Not Run
A23: TC-20 | B23: FR13 | C23: Income = 0 / saving rate | D23: Tháng không phát sinh thu | E23: Hiển thị N/A, không NaN hoặc Infinity | F23: Phạm Nguyễn Tuấn Kiệt | G23: Võ Trịnh Quốc Huy | H23: P1 | I23: Not Run
A24: TC-21 | B24: FR13 | C24: Báo cáo loại reversal/transfer | D24: Đối chiếu báo cáo tháng với ledger SQL | E24: Chart/tổng số nhất quán | F24: Phạm Nguyễn Tuấn Kiệt | G24: Võ Trịnh Quốc Huy | H24: P1 | I24: Not Run
A25: TC-22 | B25: FR16 | C25: CSV chứa công thức độc hại | D25: Tên giao dịch bắt đầu bằng =,+,-,@ | E25: Escape khi mở Excel, file UTF-8 tiếng Việt | F25: Võ Văn Khôi Nguyên | G25: Nguyễn Thành Trung | H25: P1 | I25: Not Run
A26: TC-23 | B26: FR16 | C26: Đối soát mismatch | D26: Cố tình tạo khác biệt cache/ledger trên DB test | E26: Server trả mismatch; UI không nói 'khớp' giả | F26: Võ Văn Khôi Nguyên | G26: Võ Trịnh Quốc Huy | H26: P1 | I26: Not Run
A27: TC-24 | B27: FR15 | C27: Admin không xem chi tiết tiền cá nhân | D27: Admin truy vấn API tài chính user khác | E27: Từ chối, có audit nếu hành động quản trị | F27: Võ Trịnh Quốc Huy | G27: Nguyễn Thành Trung | H27: P1 | I27: Not Run
A28: TC-25 | B28: NFR02 | C28: Chạy song song SE & LTW | D28: Start/stop SE 8080/3307, LTW 8000/3306 vẫn chạy | E28: Không ghi đè htdocs, datadir, DB khác | F28: Võ Trịnh Quốc Huy | G28: Nguyễn Thành Trung | H28: P1 | I28: Not Run
... A31: TC-28 | B31: NFR01 | C31: SQL injection, XSS, null/negative amount | D31: Nhập chuỗi độc hại và số tiền không hợp lệ | E31: Backend từ chối 422; output escape; không lộ stack | F31: Võ Trịnh Quốc Huy | G31: Phạm Nguyễn Tuấn Kiệt | H31: P1 | I31: Not Run

Sheet Sprint
A1: WEALTHFLOW | KẾ HOẠCH 4 SPRINT & GATE
A2: Ngày đề xuất để lập kế hoạch, không phải deadline chính thức của giảng viên. Cập nhật trước khi chốt phân công nhóm.
A4: Sprint | B4: Bắt đầu | C4: Kết thúc | D4: Tên | E4: Mục tiêu | F4: Đầu ra phải có | G4: Điều phối | H4: Điều kiện qua Gate
A5: S1 | B5: 46314 | C5: 46320 | D5: Khảo sát & hợp đồng | E5: Đọc code, chạy baseline, chốt ERD/schema, API contract, auth/OTP, seed | F5: Baseline report + ERD + data dictionary + test auth + Git convention | G5: Huy | H5: Gate: request/response đã chốt và local chạy riêng
A6: S2 | B6: 46321 | C6: 46327 | D6: E2E core finance | E6: Wallets/categories/transfers/ledger/recurring và budget từ MySQL | F6: Dữ liệu tạo xong reload còn; test FR03–06 và MySQL thật | G6: Khôi Nguyên / Tuấn Kiệt | H6: Gate: không còn số liệu fixture ở module cốt lõi
A7: S3 | B7: 46328 | C7: 46334 | D7: Wealth & Microfinance | E7: Savings, loans, gold, net worth, report, dashboard API | F7: KPI tài sản, báo cáo SQL đúng, microfinance có CRUD thật | G7: Tuấn Kiệt / Huy | H7: Gate: NetWorth đúng, khoản vay không hạch toán sai
A8: S4 | B8: 46335 | C8: 46341 | D8: QA / Docs / Demo | E8: E2E, bảo mật, backup, release, SRS/UML và bằng chứng | F8: PR reviewed, test Pass, file SRS/ERD, demo script | G8: Cả nhóm; Trung lead docs | H8: Gate: không có lỗi P1 trước nghiệm thu
A11: CHECKPOINT NHÓM (ĐỀ XUẤT)
A12: Thời điểm | B12: Thời lượng | C12: Mục tiêu | D12: Bằng chứng tối thiểu | E12: Điều phối
A13: Thứ 2 | B13: 15–20 phút | C13: Chốt task trong tuần | D13: Mỗi người chọn task + branch và phụ thuộc | E13: Huy
A14: Thứ 4 | B14: 15 phút | C14: Cập nhật blockers | D14: Báo API/schema conflict sớm, đẩy PR nhỏ | E14: Huy & Trung
A15: Thứ 7 | B15: 30–45 phút | C15: Sprint review + demo | D15: Mỗi dev demo thao tác trên DB thật, trình bằng chứng | E15: 4 thành viên
A16: Chủ nhật | B16: 30 phút | C16: Review tài liệu & test | D16: Trung cập nhật SRS/ERD/Test report; Huy chốt gate | E16: Trung & Huy
A19: DEFINITION OF DONE – ĐIỀU KIỆN ĐỔI TASK THÀNH DONE
A20: 1 | B20: Code đã được PR review & merge, không commit secret vào Git.
A21: 2 | B21: Luồng UI → API PHP → MySQL 3307 chạy thành công và không dùng dữ liệu mock để giả làm thành công.
A22: 3 | B22: Có ít nhất 1 happy path + 1 negative path; 2 user test isolation với mọi tính năng tài chính.
A23: 4 | B23: Không phá luồng ví/giao dịch/ngân sách sau merge; có rollback/backup khi migration.
A24: 5 | B24: Có video/ảnh test, link PR và cập nhật task + tài liệu liên quan.

Sheet TaiLieu_Git
A1: WEALTHFLOW | TÀI LIỆU, GIT WORKFLOW & NGUỒN KIỂM CHỨNG
A2: Có thể chép checklist này vào docs/ và dùng làm mục lục cho báo cáo cuối kỳ. Đây là danh mục cần tạo/cập nhật, KHÔNG khẳng định file đã tồn tại.
A4: ID | B4: File đề xuất | C4: Nội dung | D4: Chủ trì | E4: Sprint | F4: Tiêu chí chất lượng
A5: DOC-01 | B5: docs/implementation-status.md | C5: Baseline tính năng / fixture / API / E2E | D5: Huy | E5: S1 | F5: UI nào đã chạy thật; evidence screenshot; commit hash
A6: DOC-02 | B6: docs/SRS.md | C6: IEEE 830 (rút gọn phù hợp phạm vi) | D6: Trung | E6: S4 | F6: Mục tiêu, actor, FR/NFR, constraints, use case, business rules
A7: DOC-03 | B7: docs/erd.mmd, docs/erd.png | C7: ERD và khóa/ràng buộc | D7: Trung | E7: S1/S4 | F7: Schema thực + type PK/FK/cardinality, không giả tên bảng
A8: DOC-04 | B8: docs/data-dictionary.md | C8: Từ điển dữ liệu | D8: Trung | E8: S1/S4 | F8: Entity/field/type/nullable/default/index, ownership
A9: DOC-05 | B9: docs/api-contract.md | C9: Hợp đồng API PHP/JSON | D9: Huy | E9: S1 | F9: Path/method/body/response/error/auth/role, mẫu request/response
A10: DOC-06 | B10: docs/finance-rules.md | C10: Quy tắc kế toán/logic | D10: Tuấn Kiệt, Trung hỗ trợ | E10: S1/S3 | F10: BR01–BR12; nguồn số liệu, các ngoại lệ, cách tính
A11: DOC-07 | B11: docs/uml/ | C11: Use Case, Activity, Sequence, Component | D11: Trung | E11: S4 | F11: Đăng nhập, thu-chi, ngân sách, mục tiêu, vay/nhắc nợ
A12: DOC-08 | B12: docs/db-test-parity.md | C12: Khác biệt SQLite vs MySQL | D12: Trung | E12: S2 | F12: Ràng buộc FK, type DECIMAL và test E2E
A13: DOC-09 | B13: docs/test-evidence/ | C13: Test case, screenshot và SQL đối chiếu | D13: Tất cả (Trung tổng hợp) | E13: S4 | F13: Pass/fail/bug ID, ảnh minh chứng và ngày test
A14: DOC-10 | B14: docs/setup.md | C14: Cài đặt trên Windows XAMPP | D14: Huy + Trung | E14: S4 | F14: SE 8080/3307; không ảnh hưởng LTW 8000/3306
A15: DOC-11 | B15: docs/backup-restore.md | C15: Sao lưu, phục hồi SE MySQL | D15: Trung | E15: S3 | F15: Dump/restore thử và logs, không xóa dữ liệu LTW
... A17: DOC-13 | B17: docs/REPORT.md | C17: Báo cáo kết quả và đóng góp | D17: Trung, Huy duyệt | E17: S4 | F17: Mục tiêu, thiết kế, hiện thực, test, hạn chế, roadmap
A20: GIT FLOW – ÁP DỤNG CHO NHÓM CÓ 3 DEV SONG SONG
A21: Bước | B21: Lệnh/Thao tác | C21: Nguyên tắc | D21: Phụ trách
A22: 1. Đồng bộ | B22: git checkout main && git pull origin main | C22: Chỉ dùng main làm đường cơ sở; không code trực tiếp lên main | D22: Trước mỗi task
A23: 2. Tạo branch | B23: git checkout -b feature/tx-04-post-expense | C23: Tên branch theo ID task; ví dụ feature/plan-06-goals | D23: Nguyên, Kiệt, Huy
A24: 3. Commit | B24: git add <đường-dẫn-đã-chọn> && git commit -m "feat(tx): implement posted expense [TX-04]" | C24: Chỉ add file cần; không `git add .` vô thức với secrets | D24: Mỗi PR nhỏ
A25: 4. Push | B25: git push -u origin feature/tx-04-post-expense | C25: Đưa branch lên origin, chưa đụng main | D25: Dev owner
A26: 5. PR | B26: Open PR → main; mô tả task ID, test, screenshot, migration | C26: Huy review PHP & giao diện; Trung review SQL; 1 review trước merge | D26: Dev + reviewer
A27: 6. Merge & QA | B27: Merge PR khi test PASS; `git pull origin main` | C27: Dùng merge chuẩn; force-push main chỉ khi cả nhóm đồng ý và backup | D27: Huy
A28: 7. Fix conflict | B28: git fetch origin; git rebase origin/main (trên feature branch) | C28: Không rebase main, không xóa code người khác; báo owner file xung đột | D28: Dev liên quan
A29: 8. Release | B29: Tag v0.1-demo sau test; lưu backup SQL | C29: Kèm danh sách tính năng thật, known issues và bằng chứng | D29: Huy + Trung
A32: NGUỒN GỐC TỪ GITHUB – KIỂM TRA NGÀY 18/10/2026
A33: Nguồn | B33: Địa chỉ | C33: Phạm vi xác nhận
A34: Repository | B34: https://github.com/huytothevoz/SE---Microfinance-Personal-Wealth-Expense-Tracker | C34: Cấu trúc source/docs, scripts chạy SE
A35: README | B35: https://github.com/huytothevoz/SE---Microfinance-Personal-Wealth-Expense-Tracker/blob/main/README.md | C35: Backend FR03–FR06 unit test; UI mock; cách test
A36: Frontend pages | B36: https://github.com/huytothevoz/SE---Microfinance-Personal-Wealth-Expense-Tracker/blob/main/source/frontend/js/app/pages.js | C36: Các trang ví, giao dịch, budget, định kỳ, goal, loan, gold, report, admin
A37: Backend tests | B37: https://github.com/huytothevoz/SE---Microfinance-Personal-Wealth-Expense-Tracker/blob/main/source/backend/tests/run_tests.php | C37: Double-entry, transfer, reversal, FX, threshold, recurring worker
A38: Setup guide | B38: https://github.com/huytothevoz/SE---Microfinance-Personal-Wealth-Expense-Tracker/blob/main/HUONG_DAN.txt | C38: PHP 8080 + MySQL 3307 chạy độc lập, an toàn LTW
A41: RISKS & QUY TẮC AN TOÀN DỰ ÁN
A42: Mã | B42: Rủi ro | C42: Biện pháp
A43: R1 | B43: Mock data giả hoàn thiện | C43: Bỏ fixture theo module sau khi API chạy; demo chỉ số thực; ghi rõ giới hạn
A44: R2 | B44: Xung đột Git trong pages.js | C44: Tách module khi triển khai; dùng branch nhỏ và leader điều phối merge
A45: R3 | B45: Lỗi khác biệt SQLite/MySQL | C45: Chạy tests cả hai, kiểm FK/DECIMAL và rollback DB khi thất bại
A46: R4 | B46: Setup xóa htdocs/DB LTW | C46: Chỉ dùng runner mới; không chạy setup cũ; bảo toàn 3306 và project LTW
A47: R5 | B47: Dữ liệu tài chính người khác | C47: Always derive userId from session; test IDOR; không commit secrets
A48: R6 | B48: Ghi nhận khoản vay sai | C48: Nhận tiền vay không phải income; trả gốc không phải expense; double-count net worth
...
